WARNING 2025-02-08 14:53:35,144 basehttp "GET /auth/change_email HTTP/1.1" 404 8126
WARNING 2025-02-08 14:54:14,598 basehttp "GET /auth/change_email HTTP/1.1" 404 8126
WARNING 2025-02-08 14:54:15,273 basehttp "GET /auth/change_email HTTP/1.1" 404 8126
WARNING 2025-02-08 14:54:17,276 basehttp "GET /auth/change_email HTTP/1.1" 404 8126
WARNING 2025-02-08 22:21:27,183 basehttp "GET /favicon.ico HTTP/1.1" 404 6196
ERROR 2025-02-08 22:26:29,397 log Internal Server Error: /contacts/
Traceback (most recent call last):
  File "/usr/local/lib/python3.11/site-packages/django/template/base.py", line 510, in parse
    compile_func = self.tags[command]
                   ~~~~~~~~~^^^^^^^^^
KeyError: 'endblock'

During handling of the above exception, another exception occurred:

Traceback (most recent call last):
  File "/usr/local/lib/python3.11/site-packages/django/core/handlers/exception.py", line 55, in inner
    response = get_response(request)
               ^^^^^^^^^^^^^^^^^^^^^
  File "/usr/local/lib/python3.11/site-packages/django/core/handlers/base.py", line 197, in _get_response
    response = wrapped_callback(request, *callback_args, **callback_kwargs)
               ^^^^^^^^^^^^^^^^^^^^^^^^^^^^^^^^^^^^^^^^^^^^^^^^^^^^^^^^^^^^
  File "/app/app/views.py", line 94, in contacts
    return render(request, "./contacts/index.html", {"form": form})
           ^^^^^^^^^^^^^^^^^^^^^^^^^^^^^^^^^^^^^^^^^^^^^^^^^^^^^^^^
  File "/usr/local/lib/python3.11/site-packages/django/shortcuts.py", line 25, in render
    content = loader.render_to_string(template_name, context, request, using=using)
              ^^^^^^^^^^^^^^^^^^^^^^^^^^^^^^^^^^^^^^^^^^^^^^^^^^^^^^^^^^^^^^^^^^^^^
  File "/usr/local/lib/python3.11/site-packages/django/template/loader.py", line 61, in render_to_string
    template = get_template(template_name, using=using)
               ^^^^^^^^^^^^^^^^^^^^^^^^^^^^^^^^^^^^^^^^
  File "/usr/local/lib/python3.11/site-packages/django/template/loader.py", line 15, in get_template
    return engine.get_template(template_name)
           ^^^^^^^^^^^^^^^^^^^^^^^^^^^^^^^^^^
  File "/usr/local/lib/python3.11/site-packages/django/template/backends/django.py", line 79, in get_template
    return Template(self.engine.get_template(template_name), self)
                    ^^^^^^^^^^^^^^^^^^^^^^^^^^^^^^^^^^^^^^^
  File "/usr/local/lib/python3.11/site-packages/django/template/engine.py", line 177, in get_template
    template, origin = self.find_template(template_name)
                       ^^^^^^^^^^^^^^^^^^^^^^^^^^^^^^^^^
  File "/usr/local/lib/python3.11/site-packages/django/template/engine.py", line 159, in find_template
    template = loader.get_template(name, skip=skip)
               ^^^^^^^^^^^^^^^^^^^^^^^^^^^^^^^^^^^^
  File "/usr/local/lib/python3.11/site-packages/django/template/loaders/cached.py", line 57, in get_template
    template = super().get_template(template_name, skip)
               ^^^^^^^^^^^^^^^^^^^^^^^^^^^^^^^^^^^^^^^^^
  File "/usr/local/lib/python3.11/site-packages/django/template/loaders/base.py", line 28, in get_template
    return Template(
           ^^^^^^^^^
  File "/usr/local/lib/python3.11/site-packages/django/template/base.py", line 154, in __init__
    self.nodelist = self.compile_nodelist()
                    ^^^^^^^^^^^^^^^^^^^^^^^
  File "/usr/local/lib/python3.11/site-packages/django/template/base.py", line 196, in compile_nodelist
    nodelist = parser.parse()
               ^^^^^^^^^^^^^^
  File "/usr/local/lib/python3.11/site-packages/django/template/base.py", line 518, in parse
    raise self.error(token, e)
  File "/usr/local/lib/python3.11/site-packages/django/template/base.py", line 516, in parse
    compiled_result = compile_func(self, token)
                      ^^^^^^^^^^^^^^^^^^^^^^^^^
  File "/usr/local/lib/python3.11/site-packages/django/template/loader_tags.py", line 295, in do_extends
    nodelist = parser.parse()
               ^^^^^^^^^^^^^^
  File "/usr/local/lib/python3.11/site-packages/django/template/base.py", line 512, in parse
    self.invalid_block_tag(token, command, parse_until)
  File "/usr/local/lib/python3.11/site-packages/django/template/base.py", line 573, in invalid_block_tag
    raise self.error(
django.template.exceptions.TemplateSyntaxError: Invalid block tag on line 4: 'endblock'. Did you forget to register or load this tag?
ERROR 2025-02-08 22:26:30,419 basehttp "GET /contacts/ HTTP/1.1" 500 161261
WARNING 2025-02-08 22:29:54,200 views Invalid form submission: <ul class="errorlist"><li>captcha<ul class="errorlist"><li>This field is required.</li></ul></li></ul>
WARNING 2025-02-08 22:30:07,057 views Invalid form submission: <ul class="errorlist"><li>captcha<ul class="errorlist"><li>This field is required.</li></ul></li></ul>
WARNING 2025-02-08 22:30:10,779 views Invalid form submission: <ul class="errorlist"><li>captcha<ul class="errorlist"><li>This field is required.</li></ul></li></ul>
WARNING 2025-02-08 22:30:15,157 views Invalid form submission: <ul class="errorlist"><li>captcha<ul class="errorlist"><li>This field is required.</li></ul></li></ul>
WARNING 2025-02-08 22:30:34,165 views Invalid form submission: <ul class="errorlist"><li>captcha<ul class="errorlist"><li>This field is required.</li></ul></li></ul>
WARNING 2025-02-08 22:30:38,584 views Invalid form submission: <ul class="errorlist"><li>captcha<ul class="errorlist"><li>This field is required.</li></ul></li></ul>
WARNING 2025-02-08 22:31:36,011 views Invalid form submission: <ul class="errorlist"><li>captcha<ul class="errorlist"><li>This field is required.</li></ul></li></ul>
WARNING 2025-02-08 22:32:28,720 views Invalid form submission: <ul class="errorlist"><li>captcha<ul class="errorlist"><li>This field is required.</li></ul></li></ul>
WARNING 2025-02-08 22:32:29,920 views Invalid form submission: <ul class="errorlist"><li>captcha<ul class="errorlist"><li>This field is required.</li></ul></li></ul>
WARNING 2025-02-08 22:32:30,644 views Invalid form submission: <ul class="errorlist"><li>captcha<ul class="errorlist"><li>This field is required.</li></ul></li></ul>
WARNING 2025-02-08 22:32:31,301 views Invalid form submission: <ul class="errorlist"><li>captcha<ul class="errorlist"><li>This field is required.</li></ul></li></ul>
WARNING 2025-02-08 22:32:31,989 views Invalid form submission: <ul class="errorlist"><li>captcha<ul class="errorlist"><li>This field is required.</li></ul></li></ul>
WARNING 2025-02-08 22:32:37,031 views Invalid form submission: <ul class="errorlist"><li>captcha<ul class="errorlist"><li>This field is required.</li></ul></li></ul>
WARNING 2025-02-08 22:33:07,663 views Invalid form submission: <ul class="errorlist"><li>captcha<ul class="errorlist"><li>This field is required.</li></ul></li></ul>
WARNING 2025-02-08 22:34:21,447 views Invalid form submission: <ul class="errorlist"><li>captcha<ul class="errorlist"><li>This field is required.</li></ul></li></ul>
WARNING 2025-02-08 22:35:04,213 views Invalid form submission: <ul class="errorlist"><li>captcha<ul class="errorlist"><li>This field is required.</li></ul></li></ul>
WARNING 2025-02-08 22:35:07,768 views Invalid form submission: <ul class="errorlist"><li>captcha<ul class="errorlist"><li>This field is required.</li></ul></li></ul>
WARNING 2025-02-08 22:35:09,860 views Invalid form submission: <ul class="errorlist"><li>captcha<ul class="errorlist"><li>This field is required.</li></ul></li></ul>
WARNING 2025-02-08 22:42:48,647 views Invalid form submission: <ul class="errorlist"><li>captcha<ul class="errorlist"><li>This field is required.</li></ul></li></ul>
WARNING 2025-02-08 22:43:27,427 views Invalid form submission: <ul class="errorlist"><li>captcha<ul class="errorlist"><li>This field is required.</li></ul></li></ul>
WARNING 2025-02-08 22:43:29,223 views Invalid form submission: <ul class="errorlist"><li>captcha<ul class="errorlist"><li>This field is required.</li></ul></li></ul>
WARNING 2025-02-08 22:43:33,328 views Invalid form submission: <ul class="errorlist"><li>captcha<ul class="errorlist"><li>This field is required.</li></ul></li></ul>
WARNING 2025-02-08 22:43:37,969 views Invalid form submission: <ul class="errorlist"><li>captcha<ul class="errorlist"><li>This field is required.</li></ul></li></ul>
WARNING 2025-02-08 22:43:40,736 views Invalid form submission: <ul class="errorlist"><li>captcha<ul class="errorlist"><li>This field is required.</li></ul></li></ul>
ERROR 2025-02-08 22:50:34,117 log Internal Server Error: /contacts/
Traceback (most recent call last):
  File "/usr/local/lib/python3.11/site-packages/django/core/handlers/exception.py", line 55, in inner
    response = get_response(request)
               ^^^^^^^^^^^^^^^^^^^^^
  File "/usr/local/lib/python3.11/site-packages/django/core/handlers/base.py", line 197, in _get_response
    response = wrapped_callback(request, *callback_args, **callback_kwargs)
               ^^^^^^^^^^^^^^^^^^^^^^^^^^^^^^^^^^^^^^^^^^^^^^^^^^^^^^^^^^^^
  File "/app/app/views.py", line 86, in contacts
    message = form.changed_data["message"]
              ~~~~~~~~~~~~~~~~~^^^^^^^^^^^
TypeError: list indices must be integers or slices, not str
ERROR 2025-02-08 22:50:34,126 basehttp "POST /contacts/ HTTP/1.1" 500 62745
ERROR 2025-02-08 22:51:13,795 log Internal Server Error: /contacts/
Traceback (most recent call last):
  File "/usr/local/lib/python3.11/site-packages/django/core/handlers/exception.py", line 55, in inner
    response = get_response(request)
               ^^^^^^^^^^^^^^^^^^^^^
  File "/usr/local/lib/python3.11/site-packages/django/core/handlers/base.py", line 197, in _get_response
    response = wrapped_callback(request, *callback_args, **callback_kwargs)
               ^^^^^^^^^^^^^^^^^^^^^^^^^^^^^^^^^^^^^^^^^^^^^^^^^^^^^^^^^^^^
  File "/app/app/views.py", line 86, in contacts
    message = form.changed_data["message"]
              ~~~~~~~~~~~~~~~~~^^^^^^^^^^^
TypeError: list indices must be integers or slices, not str
ERROR 2025-02-08 22:51:13,802 basehttp "POST /contacts/ HTTP/1.1" 500 62745
ERROR 2025-02-08 22:51:14,468 log Internal Server Error: /contacts/
Traceback (most recent call last):
  File "/usr/local/lib/python3.11/site-packages/django/core/handlers/exception.py", line 55, in inner
    response = get_response(request)
               ^^^^^^^^^^^^^^^^^^^^^
  File "/usr/local/lib/python3.11/site-packages/django/core/handlers/base.py", line 197, in _get_response
    response = wrapped_callback(request, *callback_args, **callback_kwargs)
               ^^^^^^^^^^^^^^^^^^^^^^^^^^^^^^^^^^^^^^^^^^^^^^^^^^^^^^^^^^^^
  File "/app/app/views.py", line 86, in contacts
    message = form.changed_data["message"]
              ~~~~~~~~~~~~~~~~~^^^^^^^^^^^
TypeError: list indices must be integers or slices, not str
ERROR 2025-02-08 22:51:14,471 basehttp "POST /contacts/ HTTP/1.1" 500 62745
ERROR 2025-02-08 22:51:15,970 log Internal Server Error: /contacts/
Traceback (most recent call last):
  File "/usr/local/lib/python3.11/site-packages/django/core/handlers/exception.py", line 55, in inner
    response = get_response(request)
               ^^^^^^^^^^^^^^^^^^^^^
  File "/usr/local/lib/python3.11/site-packages/django/core/handlers/base.py", line 197, in _get_response
    response = wrapped_callback(request, *callback_args, **callback_kwargs)
               ^^^^^^^^^^^^^^^^^^^^^^^^^^^^^^^^^^^^^^^^^^^^^^^^^^^^^^^^^^^^
  File "/app/app/views.py", line 86, in contacts
    message = form.changed_data["message"]
              ~~~~~~~~~~~~~~~~~^^^^^^^^^^^
TypeError: list indices must be integers or slices, not str
ERROR 2025-02-08 22:51:15,976 basehttp "POST /contacts/ HTTP/1.1" 500 62745
WARNING 2025-02-08 23:17:52,446 basehttp "GET /auth/update_email HTTP/1.1" 404 7892
WARNING 2025-02-08 23:17:54,669 basehttp "GET /auth/update_email HTTP/1.1" 404 7892
WARNING 2025-02-08 23:17:56,843 basehttp "GET /auth/update_email HTTP/1.1" 404 7892
WARNING 2025-02-08 23:18:40,853 basehttp "GET /profile/update_email HTTP/1.1" 404 7087
WARNING 2025-02-08 23:18:43,399 basehttp "GET /profile/update_email HTTP/1.1" 404 7087
WARNING 2025-02-08 23:18:50,502 basehttp "GET /profile/update_email HTTP/1.1" 404 7087
WARNING 2025-02-08 23:18:58,904 basehttp "GET /profile/update_username HTTP/1.1" 404 7096
WARNING 2025-02-09 10:33:56,617 basehttp "GET /favicon.ico HTTP/1.1" 404 7060
WARNING 2025-02-09 10:48:58,591 basehttp "GET /faq HTTP/1.1" 404 7036
WARNING 2025-02-09 10:49:18,018 basehttp "GET /faq HTTP/1.1" 404 7279
WARNING 2025-02-09 11:22:11,314 basehttp "GET /delivery_trems HTTP/1.1" 404 7306
WARNING 2025-02-09 11:22:21,242 basehttp "GET /delivery_trems HTTP/1.1" 404 7306
ERROR 2025-02-09 11:22:41,053 log Internal Server Error: /profile/settings/update_username/
Traceback (most recent call last):
  File "/usr/local/lib/python3.11/site-packages/django/db/backends/utils.py", line 105, in _execute
    return self.cursor.execute(sql, params)
           ^^^^^^^^^^^^^^^^^^^^^^^^^^^^^^^^
psycopg2.errors.UniqueViolation: duplicate key value violates unique constraint "authapp_customuser_username_key"
DETAIL:  Key (username)=(admin) already exists.


The above exception was the direct cause of the following exception:

Traceback (most recent call last):
  File "/usr/local/lib/python3.11/site-packages/django/core/handlers/exception.py", line 55, in inner
    response = get_response(request)
               ^^^^^^^^^^^^^^^^^^^^^
  File "/usr/local/lib/python3.11/site-packages/django/core/handlers/base.py", line 197, in _get_response
    response = wrapped_callback(request, *callback_args, **callback_kwargs)
               ^^^^^^^^^^^^^^^^^^^^^^^^^^^^^^^^^^^^^^^^^^^^^^^^^^^^^^^^^^^^
  File "/usr/local/lib/python3.11/site-packages/django/contrib/auth/decorators.py", line 60, in _view_wrapper
    return view_func(request, *args, **kwargs)
           ^^^^^^^^^^^^^^^^^^^^^^^^^^^^^^^^^^^
  File "/app/app/views.py", line 185, in update_username
    user.save()
  File "/usr/local/lib/python3.11/site-packages/django/contrib/auth/base_user.py", line 62, in save
    super().save(*args, **kwargs)
  File "/usr/local/lib/python3.11/site-packages/django/db/models/base.py", line 892, in save
    self.save_base(
  File "/usr/local/lib/python3.11/site-packages/django/db/models/base.py", line 998, in save_base
    updated = self._save_table(
              ^^^^^^^^^^^^^^^^^
  File "/usr/local/lib/python3.11/site-packages/django/db/models/base.py", line 1130, in _save_table
    updated = self._do_update(
              ^^^^^^^^^^^^^^^^
  File "/usr/local/lib/python3.11/site-packages/django/db/models/base.py", line 1195, in _do_update
    return filtered._update(values) > 0
           ^^^^^^^^^^^^^^^^^^^^^^^^
  File "/usr/local/lib/python3.11/site-packages/django/db/models/query.py", line 1278, in _update
    return query.get_compiler(self.db).execute_sql(CURSOR)
           ^^^^^^^^^^^^^^^^^^^^^^^^^^^^^^^^^^^^^^^^^^^^^^^
  File "/usr/local/lib/python3.11/site-packages/django/db/models/sql/compiler.py", line 2003, in execute_sql
    cursor = super().execute_sql(result_type)
             ^^^^^^^^^^^^^^^^^^^^^^^^^^^^^^^^
  File "/usr/local/lib/python3.11/site-packages/django/db/models/sql/compiler.py", line 1574, in execute_sql
    cursor.execute(sql, params)
  File "/usr/local/lib/python3.11/site-packages/django/db/backends/utils.py", line 122, in execute
    return super().execute(sql, params)
           ^^^^^^^^^^^^^^^^^^^^^^^^^^^^
  File "/usr/local/lib/python3.11/site-packages/django/db/backends/utils.py", line 79, in execute
    return self._execute_with_wrappers(
           ^^^^^^^^^^^^^^^^^^^^^^^^^^^^
  File "/usr/local/lib/python3.11/site-packages/django/db/backends/utils.py", line 92, in _execute_with_wrappers
    return executor(sql, params, many, context)
           ^^^^^^^^^^^^^^^^^^^^^^^^^^^^^^^^^^^^
  File "/usr/local/lib/python3.11/site-packages/django/db/backends/utils.py", line 100, in _execute
    with self.db.wrap_database_errors:
  File "/usr/local/lib/python3.11/site-packages/django/db/utils.py", line 91, in __exit__
    raise dj_exc_value.with_traceback(traceback) from exc_value
  File "/usr/local/lib/python3.11/site-packages/django/db/backends/utils.py", line 105, in _execute
    return self.cursor.execute(sql, params)
           ^^^^^^^^^^^^^^^^^^^^^^^^^^^^^^^^
django.db.utils.IntegrityError: duplicate key value violates unique constraint "authapp_customuser_username_key"
DETAIL:  Key (username)=(admin) already exists.

ERROR 2025-02-09 11:22:41,064 basehttp "POST /profile/settings/update_username/ HTTP/1.1" 500 150288
WARNING 2025-02-09 21:13:07,697 basehttp "GET /favicon.ico HTTP/1.1" 404 7297
WARNING 2025-02-09 21:18:45,237 basehttp "GET /delivery_trems HTTP/1.1" 404 7306
WARNING 2025-02-09 21:18:56,053 basehttp "GET /delivery_trems HTTP/1.1" 404 7306
WARNING 2025-02-10 22:36:24,381 basehttp "GET /favicon.ico HTTP/1.1" 404 7297
WARNING 2025-02-14 23:42:49,643 basehttp "GET /favicon.ico HTTP/1.1" 404 7297
WARNING 2025-02-16 10:12:43,545 basehttp "GET /favicon.ico HTTP/1.1" 404 7297
WARNING 2025-02-22 17:55:17,761 basehttp "GET /favicon.ico HTTP/1.1" 404 7297
WARNING 2025-02-22 18:17:05,941 basehttp "GET /s HTTP/1.1" 404 7267
WARNING 2025-02-22 18:52:02,055 basehttp "GET /robots.txt HTTP/1.1" 404 7294
WARNING 2025-02-22 18:53:13,564 basehttp "GET /robots.txt HTTP/1.1" 404 7294
WARNING 2025-02-22 18:53:56,803 basehttp "GET /robots.txt HTTP/1.1" 404 7294
WARNING 2025-03-01 10:31:01,714 basehttp "GET /favicon.ico HTTP/1.1" 404 7297
